Traceback (most recent call last):
  File "run_server.py", line 3, in <module>
    app.run()
  File "/home/pi/code/smart-water-heater-controller/server/app.py", line 53, in run
    app.run(host="0.0.0.0")
  File "/usr/lib/python3/dist-packages/flask/app.py", line 841, in run
    run_simple(host, port, self, **options)
  File "/usr/lib/python3/dist-packages/werkzeug/serving.py", line 708, in run_simple
    inner()
  File "/usr/lib/python3/dist-packages/werkzeug/serving.py", line 670, in inner
    fd=fd)
  File "/usr/lib/python3/dist-packages/werkzeug/serving.py", line 564, in make_server
    passthrough_errors, ssl_context, fd=fd)
  File "/usr/lib/python3/dist-packages/werkzeug/serving.py", line 476, in __init__
    HTTPServer.__init__(self, (host, int(port)), handler)
  File "/usr/lib/python3.5/socketserver.py", line 440, in __init__
    self.server_bind()
  File "/usr/lib/python3.5/http/server.py", line 138, in server_bind
    socketserver.TCPServer.server_bind(self)
  File "/usr/lib/python3.5/socketserver.py", line 454, in server_bind
    self.socket.bind(self.server_address)
OSError: [Errno 98] Address already in use
Traceback (most recent call last):
  File "run_server.py", line 3, in <module>
    app.run()
  File "/home/pi/code/smart-water-heater-controller/server/app.py", line 53, in run
    app.run(host="0.0.0.0")
  File "/usr/lib/python3/dist-packages/flask/app.py", line 841, in run
    run_simple(host, port, self, **options)
  File "/usr/lib/python3/dist-packages/werkzeug/serving.py", line 708, in run_simple
    inner()
  File "/usr/lib/python3/dist-packages/werkzeug/serving.py", line 670, in inner
    fd=fd)
  File "/usr/lib/python3/dist-packages/werkzeug/serving.py", line 564, in make_server
    passthrough_errors, ssl_context, fd=fd)
  File "/usr/lib/python3/dist-packages/werkzeug/serving.py", line 476, in __init__
    HTTPServer.__init__(self, (host, int(port)), handler)
  File "/usr/lib/python3.5/socketserver.py", line 440, in __init__
    self.server_bind()
  File "/usr/lib/python3.5/http/server.py", line 138, in server_bind
    socketserver.TCPServer.server_bind(self)
  File "/usr/lib/python3.5/socketserver.py", line 454, in server_bind
    self.socket.bind(self.server_address)
OSError: [Errno 98] Address already in use
Traceback (most recent call last):
  File "run_server.py", line 3, in <module>
    app.run()
  File "/home/pi/code/smart-water-heater-controller/server/app.py", line 53, in run
    app.run(host="0.0.0.0")
  File "/usr/lib/python3/dist-packages/flask/app.py", line 841, in run
    run_simple(host, port, self, **options)
  File "/usr/lib/python3/dist-packages/werkzeug/serving.py", line 708, in run_simple
    inner()
  File "/usr/lib/python3/dist-packages/werkzeug/serving.py", line 670, in inner
    fd=fd)
  File "/usr/lib/python3/dist-packages/werkzeug/serving.py", line 564, in make_server
    passthrough_errors, ssl_context, fd=fd)
  File "/usr/lib/python3/dist-packages/werkzeug/serving.py", line 476, in __init__
    HTTPServer.__init__(self, (host, int(port)), handler)
  File "/usr/lib/python3.5/socketserver.py", line 440, in __init__
    self.server_bind()
  File "/usr/lib/python3.5/http/server.py", line 138, in server_bind
    socketserver.TCPServer.server_bind(self)
  File "/usr/lib/python3.5/socketserver.py", line 454, in server_bind
    self.socket.bind(self.server_address)
OSError: [Errno 98] Address already in use
